{
  "comments": [
    {
      "key": {
        "uuid": "f49ab324_25991f80",
        "filename": "appengine/findit/services/flake_failure/data_point_util.py",
        "patchSetId": 4
      },
      "lineNbr": 127,
      "author": {
        "id": 1157909
      },
      "writtenOn": "2018-05-03T21:43:33Z",
      "side": 1,
      "message": "remove",
      "range": {
        "startLine": 127,
        "startChar": 36,
        "endLine": 127,
        "endChar": 37
      },
      "revId": "e4a675b0856e2954890a183c821d838a428a0c84",
      "serverId": "3ce6091f-6c88-37e8-8c75-72f92ae8dfba",
      "unresolved": true
    }
  ]
}