[
  {
    "cmd": [],
    "name": "RECIPE CRASH (Uncaught exception)",
    "~followup_annotations": [
      "@@@STEP_EXCEPTION@@@",
      "The recipe has crashed at point 'Uncaught exception'!",
      "",
      "Traceback (most recent call last):",
      "  File \"RECIPE_REPO[recipe_engine]/recipe_engine/internal/engine.py\", in run_steps",
      "    raw_result = recipe_obj.run_steps(api, engine)",
      "                 ^^^^^^^^^^^^^^^^^^^^^^^^^^^^^^^^^",
      "  File \"RECIPE_REPO[recipe_engine]/recipe_engine/internal/recipe_deps.py\", in run_steps",
      "    recipe_result = invoke_with_properties(",
      "                    ^^^^^^^^^^^^^^^^^^^^^^^",
      "  File \"RECIPE_REPO[recipe_engine]/recipe_engine/internal/property_invoker.py\", in invoke_with_properties",
      "    return _invoke_with_properties(callable_obj, all_props, environ, prop_defs,",
      "           ^^^^^^^^^^^^^^^^^^^^^^^^^^^^^^^^^^^^^^^^^^^^^^^^^^^^^^^^^^^^^^^^^^^^",
      "  File \"RECIPE_REPO[recipe_engine]/recipe_engine/internal/property_invoker.py\", in _invoke_with_properties",
      "    return callable_obj(*props, **additional_args)",
      "           ^^^^^^^^^^^^^^^^^^^^^^^^^^^^^^^^^^^^^^^",
      "  File \"RECIPE_REPO[infra]/recipes/recipes/recipe_roll_tryjob.py\", line 417, in RunSteps",
      "    assert change is not None, 'no change found from upstream repo'",
      "           ^^^^^^^^^^^^^^^^^^",
      "AssertionError: no change found from upstream repo"
    ]
  },
  {
    "failure": {
      "humanReason": "Uncaught Exception: AssertionError('no change found from upstream repo')"
    },
    "name": "$result"
  }
]